Workbook
Name Architectural_Fabric_Component: Lists!$C$66:$C$79
Name Architectural_Fabric_Subsystem: Lists!$B$66:$B$74
Name Compliance_Documentation_Component: Lists!#REF!
Name Compliance_Documentation_Subsystem: Lists!#REF!
Name Digital_ICT_Component: Lists!$C$136:$C$149
Name Digital_ICT_Subsystem: Lists!$B$130:$B$144
Name Electrical_Component: Lists!#REF!
Name Electrical_Subsystem: Lists!#REF!
Name EvidenceType: Lists!#REF!
Name External_Parking_Component: Lists!$C$80:$C$93
Name External_Parking_Subsystem: Lists!$B$80:$B$88
Name FindingCategory: Lists!#REF!
Name FM_Performance_Component: Lists!$C$178:$C$192
Name FM_Performance_Subsystem: Lists!$B$178:$B$187
Name Landscape_Component: Lists!#REF!
Name Landscape_Subsystem: Lists!#REF!
Name LIST_EVIDENCE: Lists!#REF!
Name LIST_FINDCAT: Lists!#REF!
Name LIST_PRIORITY: Lists!#REF!
Name LIST_RATINGS: Lists!#REF!
Name LIST_STATUS: Lists!#REF!
Name Mechanical_HVAC_Component: Lists!#REF!
Name Mechanical_HVAC_Subsystem: Lists!#REF!
Name PassFail: Lists!#REF!
Name Plumbing_Water_Component: Lists!#REF!
Name Plumbing_Water_Subsystem: Lists!#REF!
Name Pools_WaterFeatures_Component: Lists!$C$108:$C$121
Name Pools_WaterFeatures_Subsystem: Lists!$B$108:$B$116
Name Priority: Lists!#REF!
Name Rating: Lists!#REF!
Name Responsibility: Lists!$E$3:$E$9
Name Security_Safety_Component: Lists!$C$122:$C$135
Name Security_Safety_Subsystem: Lists!$B$122:$B$127
Name Status: Lists!#REF!
Name Structural_Component: Lists!$C$52:$C$65
Name Structural_Subsystem: Lists!$B$52:$B$60
Name Sustainability_Component: Lists!$C$150:$C$164
Name Sustainability_Subsystem: Lists!$B$150:$B$159
Name SystemList: Lists!#REF!

Sheet User Manual
A1: User Manual
C5: 1. Purpose of This Tool
C6: This workbook is used to perform:
C7: *Building handover and delivery inspections
C8: *Facilities Management (FM) performance audits
C9: *Asset condition, compliance, and operational readiness assessments
C10: It is a structured, weighted, and auditable checklist designed for professional and government use
C12: 2. Who Should Use This Handbook
C13: This handbook is intended for:
C14: *Inspectors
C15: *Engineers
C16: *Auditors
C17: *FM Supervisors
... C20: 3. Sheets Description
C21: Executive Assessment Summary | D21: Summarizes the overall building condition, key risks, and final acceptance status.
C22: Government Compliance Checklist | D22: Confirms compliance with applicable government regulations and approvals.
C23: Building Assessment | D23: Assesses the technical condition and performance of building systems.
C24: Test Register | D24: Logs all inspections and tests performed and their outcomes.
C25: CAPA Register | D25: Tracks corrective actions, responsibilities, and closure status.
C28: 4. How to Perform an Inspection
C29: 1. Complete project information in Executive Assessment Summary Sheet
C30: 2. Review the weigh in the Executive Assessment Summary Sheet
C31: 3. Review the weight in the Building Assessment Sheet
C32: 4. Review the Risk Criticality and priority in Building Assessment sheet.
C33: 5. Inspect each inspection item under your system and fill all the required fields in the Building Assessment Sheet
C34: 6. Review results in the Executive Assessment Summary Sheet
C35: 7. Submit the final report to the Advisory team for review
C38: 5. Guideline
C40: Rating Scale | F40: Risk Criticality
C41: Rating | D41: Meaning | F41: Risk | G41: Meaning
C42: 5 | D42: Excellent – Fully compliant | F42: 5 | G42: Critical - Severe safety or compliance risk
C43: 4 | D43: Good – Minor observations | F43: 4 | G43: High - Significant safety or operational concern
C44: 3 | D44: Fair – Acceptable | F44: 3 | G44: Medium - Moderate operational or maintenance risk
C45: 2 | D45: Poor – Non-compliant | F45: 2 | G45: Low - Minor defect with limited impact
C46: 1 | D46: Critical – Unacceptable | F46: 1 | G46: Observation - Non-critical finding
C47: 0 | D47: Not Applicable | F47: 0 | G47: Not Applicable
C49: Priority Levels
C50: Priority | D50: Meaning
C51: P1 | D51: Critical / Safety risk
C52: P2 | D52: High
...

Sheet Executive Assessment Summary
A1: Assessment Summary | E1: Executive Assessment Summary
C2: Project Information
D4: Please fill the details | G4: Please fill the details
C5: Project / Building Name | D5: ****** | F5: Building Type | G5: REINFORCED CONCRETE (RC)
C6: City | D6: Riyadh | F6: Primary Use | G6: ADMIN
C7: Address | D7: ****** | F7: Gross Bulit Area (m²) | G7: 50000
C8: GPS Coordinates (Lat, Long) | D8: ****** | F8: No. of Floors | G8: 22
D11: Please fill the details | G11: Please fill the details
C12: Last Major Renovation Date | D12: 2025 | F12: Estimated Life Time | G12: 50
C13: FM Contractor / Service Provider | D13: ***** | F13: Planned Asset Retirement Year | G13: 2058
C14: Current Year | D14: 2025 | F14: System Threshold (%) | G14: 0.71
C15: Construction Year | D15: 2008 | F15: Inspection Date | G15: 45999
C17: =IF(D17=100%,"Pass",IF(D17>=G14,"Passed but Need Attention","Fail")) -> Fail | D17: =Table2[[#Totals],[Weighted Score]] -> 0.6430202 | E17: =COUNTIF('Building Assessment'!S:S,"P1")+COUNTIF('Building Assessment'!S:S,"P2") -> 183 | F17: =E68 -> 0.6115 | G17: =IF(COUNTBLANK(Table1[Status (Please Select from the list)])>0,"Not Complied", IF(COUNTIF(Table1[Status (Please Select from the list)],"<>Yes")>0,"Not Complied","Complied")) -> Not Complied
C18: Inspection Result | D18: Building Score | E18: High Priority Classificated | F18: FM Performance | G18: Government Compliance
C20: =E49 -> 0.53514 | D20: =G13-D15 -> 50 | E20: =D14-D15 -> 17 | F20: =D20-G20 -> 17.84899 | G20: =D20*D17 -> 32.15101
C21: Fire & Life Safety | D21: Total economic life | E21: Chronological (Actual) Age | F21: Estimated Effective Age | G21: Estimated Remaining life
C24: Notes:
C25: =IF( D17=100%, "1- The building achieved full compliance across all assessed systems and is approved for handover and/or operation without conditions.", IF( D17>=G14, "1- The building meets the acceptance criteria; however, some observations require corrective action and follow-up.", "1- The building failed to meet the minimum acceptance criteria and is not approved for handover and/or operation until all deficiencies are rectified and verified." ) ) -> 1- The building failed to meet the minimum acceptance criteria and is not approved for handover and/or operation until all deficiencies are rectified and verified.
C27: =IF( G17="Not Complied", "2- One or more mandatory government compliance documents were unavailable or incomplete at the time of inspection; accordingly, handover and/or operational approval remains conditional pending submission and acceptance of the required documentation.","2- All mandatory government compliance documents reviewed were available and valid at the time of inspection; however, such review is limited to apparent document validity and does not constitute regulatory or legal approval.") -> 2- One or more mandatory government compliance documents were unavailable or incomplete at the time of inspection; accordingly, handover and/or operational approval remains conditional pending submission and acceptance of the required documentation.
C30: =IF( E17=0, "3- No urgent or critical items were identified during the inspection.","3- The inspection identified priority items that require corrective action and follow-up.") -> 3- The inspection identified priority items that require corrective action and follow-up.
C47: Systems Performance
C48: System | D48: Item Count | E48: Score % | F48: Weight | G48: Weighted Score
C49: Fire_LifeSafety | D49: =COUNTIF('Building Assessment'!A:A,'Executive Assessment Summary'!C49) -> 35 | E49: =SUMIF('Building Assessment'!A:A,'Executive Assessment Summary'!C49,'Building Assessment'!O:O)/100 -> 0.53514 | F49: 17 | G49: =Table2[[#This Row],[Weight]]*Table2[[#This Row],[Score %]]/100 -> 0.0909738
C50: Electrical | D50: =COUNTIF('Building Assessment'!A:A,'Executive Assessment Summary'!C50) -> 30 | E50: =SUMIF('Building Assessment'!A:A,'Executive Assessment Summary'!C50,'Building Assessment'!O:O)/100 -> 0.73286 | F50: 10 | G50: =Table2[[#This Row],[Weight]]*Table2[[#This Row],[Score %]]/100 -> 0.073286
C51: Emergency_Power | D51: =COUNTIF('Building Assessment'!A:A,'Executive Assessment Summary'!C51) -> 5 | E51: =SUMIF('Building Assessment'!A:A,'Executive Assessment Summary'!C51,'Building Assessment'!O:O)/100 -> 0.76 | F51: 2 | G51: =Table2[[#This Row],[Weight]]*Table2[[#This Row],[Score %]]/100 -> 0.0152
C52: Mechanical_HVAC | D52: =COUNTIF('Building Assessment'!A:A,'Executive Assessment Summary'!C52) -> 35 | E52: =SUMIF('Building Assessment'!A:A,'Executive Assessment Summary'!C52,'Building Assessment'!O:O)/100 -> 0.60138 | F52: 9 | G52: =Table2[[#This Row],[Weight]]*Table2[[#This Row],[Score %]]/100 -> 0.0541242
C53: Plumbing_Water | D53: =COUNTIF('Building Assessment'!A:A,'Executive Assessment Summary'!C53) -> 35 | E53: =SUMIF('Building Assessment'!A:A,'Executive Assessment Summary'!C53,'Building Assessment'!O:O)/100 -> 0.68794 | F53: 8 | G53: =Table2[[#This Row],[Weight]]*Table2[[#This Row],[Score %]]/100 -> 0.0550352
C54: Gas_Systems | D54: =COUNTIF('Building Assessment'!A:A,'Executive Assessment Summary'!C54) -> 35 | E54: =SUMIF('Building Assessment'!A:A,'Executive Assessment Summary'!C54,'Building Assessment'!O:O)/100 -> 0.69208 | F54: 2 | G54: =Table2[[#This Row],[Weight]]*Table2[[#This Row],[Score %]]/100 -> 0.0138416
C55: Vertical_Transportation | D55: =COUNTIF('Building Assessment'!A:A,'Executive Assessment Summary'!C55) -> 35 | E55: =SUMIF('Building Assessment'!A:A,'Executive Assessment Summary'!C55,'Building Assessment'!O:O)/100 -> 0.7866 | F55: 5 | G55: =Table2[[#This Row],[Weight]]*Table2[[#This Row],[Score %]]/100 -> 0.03933
C56: BMS_Controls | D56: =COUNTIF('Building Assessment'!A:A,'Executive Assessment Summary'!C56) -> 35 | E56: =SUMIF('Building Assessment'!A:A,'Executive Assessment Summary'!C56,'Building Assessment'!O:O)/100 -> 0.6251 | F56: 6 | G56: =Table2[[#This Row],[Weight]]*Table2[[#This Row],[Score %]]/100 -> 0.037506
C57: ELV_Systems | D57: =COUNTIF('Building Assessment'!A:A,'Executive Assessment Summary'!C57) -> 28 | E57: =SUMIF('Building Assessment'!A:A,'Executive Assessment Summary'!C57,'Building Assessment'!O:O)/100 -> 0.63048 | F57: 3 | G57: =Table2[[#This Row],[Weight]]*Table2[[#This Row],[Score %]]/100 -> 0.0189144
C58: Security_Safety | D58: =COUNTIF('Building Assessment'!A:A,'Executive Assessment Summary'!C58) -> 35 | E58: =SUMIF('Building Assessment'!A:A,'Executive Assessment Summary'!C58,'Building Assessment'!O:O)/100 -> 0.67202 | F58: 3 | G58: =Table2[[#This Row],[Weight]]*Table2[[#This Row],[Score %]]/100 -> 0.0201606
C59: Digital_ICT | D59: =COUNTIF('Building Assessment'!A:A,'Executive Assessment Summary'!C59) -> 35 | E59: =SUMIF('Building Assessment'!A:A,'Executive Assessment Summary'!C59,'Building Assessment'!O:O)/100 -> 0.63684 | F59: 2 | G59: =Table2[[#This Row],[Weight]]*Table2[[#This Row],[Score %]]/100 -> 0.0127368
C60: Structural | D60: =COUNTIF('Building Assessment'!A:A,'Executive Assessment Summary'!C60) -> 35 | E60: =SUMIF('Building Assessment'!A:A,'Executive Assessment Summary'!C60,'Building Assessment'!O:O)/100 -> 0.68904 | F60: 4 | G60: =Table2[[#This Row],[Weight]]*Table2[[#This Row],[Score %]]/100 -> 0.0275616
... C69: Governance_Readiness | D69: =COUNTIF('Building Assessment'!A:A,'Executive Assessment Summary'!C69) -> 36 | E69: =SUMIF('Building Assessment'!A:A,'Executive Assessment Summary'!C69,'Building Assessment'!O:O)/100 -> 0.68 | F69: 7 | G69: =Table2[[#This Row],[Weight]]*Table2[[#This Row],[Score %]]/100 -> 0.0476
C70: Total Inspected Items | D70: =SUBTOTAL(109,Table2[Item Count]) -> 694 | E70: Total Weight | F70: =SUM(F49:F69) -> 100 | G70: =SUBTOTAL(109,Table2[Weighted Score]) -> 0.6430202
C72: This inspection was undertaken as a non-intrusive, visual, and advisory condition assessment based on information available and accessible at the time of inspection. The assessment does not constitute a statutory inspection, certification, commissioning, or authority approval, and does not replace inspections, tests, or certifications required by Civil Defense, municipalities, or other regulatory authorities.The scope of this assessment does not include detailed performance testing, commissioning, or compliance certification of life safety systems, including but not limited to fire-fighting systems, fire alarm systems, elevators, escalators, or other regulated systems, unless explicitly stated otherwise within the agreed scope of services. All findings, observations, and conclusions are limited to the apparent condition observed on the inspection date and are provided for decision-support purposes only. No express or implied warranty, guarantee, or representation is made regarding the future performance, compliance, or continued condition of the building or its systems. Dar Al Riyadh shall not be liable for any deterioration, failure, incident, non-compliance, or loss arising after the inspection date, or resulting from hidden defects, operational practices, maintenance deficiencies, design limitations, third-party actions, environmental conditions, or changes in regulatory requirements. Responsibility for regulatory compliance, operational safety, statutory approvals, and ongoing maintenance remains solely with the owner, operator, and/or appointed facility management entity.

Sheet Government Compliance Checklist
A3: Government Compliance Checklist | B3: Area | C3: Requirement | D3: Status (Please Select from the list) | E3: Evidence Required | F3: Item Code | G3: Evidence Ref | H3: Remarks
B4: Legal & Municipal Approvals | C4: Building Completion Certificate (Final) | D4: Yes | E4: Certificate copy with date & stamp | F4: GC-LA-001
B5: Legal & Municipal Approvals | C5: Occupancy License / Operational Permit | D5: Yes | E5: Valid license with classification | F5: GC-LA-002
B6: Legal & Municipal Approvals | C6: Valid Building Permit (Administrative Use) | D6: No | E6: Permit with all conditions met | F6: GC-LA-003
B7: Legal & Municipal Approvals | C7: National Address Registration (SPL) | D7: Yes | E7: Registration document with QR code | F7: GC-LA-004
B8: Legal & Municipal Approvals | C8: SBC Compliance Review Completion | D8: Yes | E8: Signed compliance checklist | F8: GC-LA-005
B9: Legal & Municipal Approvals | C9: Civil Defense Approval (Fire & Life Safety) | D9: Yes | E9: Valid certificate with expiry date | F9: GC-LA-006
B10: Utility Connections | C10: Electricity Connection Certificate (Active – SEC) | D10: Yes | E10: Connection contract & active account number | F10: GC-UC-001
B11: Utility Connections | C11: Water & Sewerage Connection (Active – NWC) | D11: Yes | E11: Connection contract & active account number | F11: GC-UC-002
B12: Utility Connections | C12: Waste Management Contract | D12: Yes | E12: Signed contract with collection schedule | F12: GC-UC-004
B13: Safety Certificates | C13: Elevator Inspection Certificate (Annual) | D13: No | E13: Current inspection certificate | F13: GC-SC-001
B14: Documentation | C14: Complete As-Built Drawing Set (All Disciplines) | D14: Yes | E14: Architectural, Structural, MEP, Fire, Security | F14: GC-DC-001
B15: Documentation | C15: Complete O&M Manuals (All Systems, Indexed) | D15: No | E15: OEM manuals + system operation guides | F15: GC-DC-002
... B35: Environmental & Sustainability | C35: Energy Efficiency Baseline Established | D35: N/A | E35: Baseline report with meter list | F35: GC-EC-005

Sheet Lists
A1: Priority | B1: Status | C1: Responsibility | D1: EvidenceType | E1: Rate/Weight | F1: Status | G1: Year | H1: Estimated Life Time | I1: System Threshold (%) | J1: PRIMARY USE | K1: Type | L1: Test Method Categories
A2: P1 | B2: Open | C2: MEP Contractor | D2: Photo | E2: 0 | F2: Yes | G2: 1900 | H2: 0 | I2: 0.5 | J2: RESIDENTIAL | K2: LOAD-BEARING MASONRY | L2: Visual Inspection
A3: P2 | B3: In Progress | C3: Main Contractor | D3: Video | E3: 1 | F3: No | G3: 1901 | H3: 1 | I3: 0.51 | J3: COMMERCIAL | K3: STEEL FRAME | L3: Functional Test
A4: P3 | B4: Closed | C4: FM Contractor | D4: Test Report | E4: 2 | F4: Partial | G4: 1902 | H4: 2 | I4: 0.52 | J4: INDUSTRIAL | K4: REINFORCED CONCRETE (RC) | L4: Pressure/Flow Measurement
A5: P4 | B5: Verified | C5: Specialist Vendor | D5: IR Scan | E5: 3 | F5: N/A | G5: 1903 | H5: 3 | I5: 0.53 | J5: INSTITUTIONAL / PUBLIC | K5: TIMBER/ WOOD FRAME | L5: Electrical Testing
B6: N/A | C6: Client/Owner | D6: Certificate | E6: 4 | G6: 1904 | H6: 4 | I6: 0.54 | J6: INFRASTRUCTURAL | K6: PRECAST/ PREFABRICATED | L6: Water/Plumbing Testing
D7: Inspector | E7: 5 | G7: 1905 | H7: 5 | I7: 0.55 | J7: AGRICULTURAL | K7: COMPOSITE | L7: Fire Safety Testing
G8: 1906 | H8: 6 | I8: 0.56 | J8: ADMIN | L8: Structural Testing
A9: System | B9: Subsystem | C9: Component | G9: 1907 | H9: 7 | I9: 0.57 | L9: HVAC Testing
A10: Fire_LifeSafety | B10: Fire Alarm | C10: Fire Alarm Control Panel | G10: 1908 | H10: 8 | I10: 0.58 | L10: Calibration & Certification
A11: Fire_LifeSafety | B11: Fire Fighting | C11: Detector | G11: 1909 | H11: 9 | I11: 0.59 | L11: Records & Documentation Review
A12: Fire_LifeSafety | B12: Smoke Control | C12: Manual Call Point | G12: 1910 | H12: 10 | I12: 0.6 | L12: System Integration Testing
A13: Fire_LifeSafety | B13: Compartmentation | C13: Sounder and Beacon | G13: 1911 | H13: 11 | I13: 0.61 | L13: Performance & Efficiency Analysis
A14: Fire_LifeSafety | B14: Emergency Lighting | C14: Voice Evacuation System | G14: 1912 | H14: 12 | I14: 0.62 | L14: Environmental & Compliance Audit
A15: Fire_LifeSafety | B15: Interfaces | C15: Fire Pump | G15: 1913 | H15: 13 | I15: 0.63 | L15: Specialist/Third-Party Reports
A16: Fire_LifeSafety | B16: Documentation | C16: Jockey Pump | G16: 1914 | H16: 14 | I16: 0.64 | L16: Operational Procedure Verification
A17: Fire_LifeSafety | B17: Training | C17: Sprinkler System | G17: 1915 | H17: 15 | I17: 0.65 | L17: Other
A18: Fire_LifeSafety | B18: Records | C18: Hydrant / Hose Reel | G18: 1916 | H18: 16 | I18: 0.66
A19: Fire_LifeSafety | C19: Fire Extinguisher | G19: 1917 | H19: 17 | I19: 0.67
A20: Fire_LifeSafety | C20: Clean Agent System | G20: 1918 | H20: 18 | I20: 0.68
A21: Fire_LifeSafety | C21: Smoke Extract Fan | G21: 1919 | H21: 19 | I21: 0.69
A22: Fire_LifeSafety | C22: Pressurization Fan | G22: 1920 | H22: 20 | I22: 0.7
A23: Fire_LifeSafety | C23: Fire / Smoke Damper | G23: 1921 | H23: 21 | I23: 0.71
A24: Fire_LifeSafety | C24: Fire Door | G24: 1922 | H24: 22 | I24: 0.72
A25: Fire_LifeSafety | C25: Fire Curtain | G25: 1923 | H25: 23 | I25: 0.73
A26: Fire_LifeSafety | C26: Firestopping System | G26: 1924 | H26: 24 | I26: 0.74
A27: Fire_LifeSafety | C27: Emergency Light | G27: 1925 | H27: 25 | I27: 0.75
A28: Fire_LifeSafety | C28: Exit Sign | G28: 1926 | H28: 26 | I28: 0.76
A29: Fire_LifeSafety | C29: Central Battery System | G29: 1927 | H29: 27 | I29: 0.77
A30: Fire_LifeSafety | C30: Elevator Recall Interface | G30: 1928 | H30: 28 | I30: 0.78
... A41: Fire_LifeSafety | C41: Fire Drill Records | G41: 1939 | H41: 39 | I41: 0.89
A42: Electrical | B42: Power Distribution | C42: Main LV Switchboard | G42: 1940 | H42: 40 | I42: 0.9
A43: Electrical | B43: Protection & Earthing | C43: Distribution Board | G43: 1941 | H43: 41 | I43: 0.91
A44: Electrical | B44: Metering & PQ | C44: Cable Containment | G44: 1942 | H44: 42 | I44: 0.92
A45: Electrical | B45: Lighting | C45: Earthing System | G45: 1943 | H45: 43 | I45: 0.93
A46: Electrical | B46: Rooms | C46: Bonding System | G46: 1944 | H46: 44 | I46: 0.94
A47: Electrical | B47: Interfaces | C47: Protection Relay / Breaker | G47: 1945 | H47: 45 | I47: 0.95
A48: Electrical | B48: Documentation | C48: RCD / ELCB | G48: 1946 | H48: 46 | I48: 0.96
A49: Electrical | B49: Spares & Safety | C49: Surge Protection Device | G49: 1947 | H49: 47 | I49: 0.97
A50: Electrical | B50: Housekeeping | C50: Power / Energy Meter | G50: 1948 | H50: 48 | I50: 0.98
...

Sheet Building Assessment
A1: System | B1: Subsystem (Please Select from the list) | C1: Component (Please Select from the list) | D1: Item Code | E1: Inspection Item | F1: Criteria | G1: Test Method | H1: Asset(s) Tag No. | I1: Snag Location | J1: Snag Evidence Ref. | K1: Snag Evidence Type (Please Select from the list) | L1: Rate (Please Select from the list) | M1: Score % | N1: Item Weight (Please Select from the list) | O1: Weighted Score | P1: Risk Criticality (0-5) | Q1: Responsibility (Please Select from the list) | R1: CAPA ID | S1: Priority (Please Select from the list) | T1: Due Date | U1: Status (Please Select from the list) | V1: Remarks | W1: .
A2: Fire_LifeSafety | B2: Fire Alarm | C2: Fire Alarm Control Panel | D2: FL-CP-001 | E2: Fire alarm control panel test | F2: All zones operational; no faults | G2: Visual Inspection | H2: FLS-03-A-001 | I2: External - Service Yard | K2: Checklist | L2: 4 | M2: =Table9[[#This Row],[Rate (Please Select from the list)]]/5 -> 0.8 | N2: 3.31 | O2: =Table9[[#This Row],[Score %]]*Table9[[#This Row],[Item Weight (Please Select from the list)]] -> 2.648 | P2: 5 | Q2: Specialist Vendor | S2: P3 | U2: Closed | V2: Inspected and found generally compliant; minor observations noted (no immediate impact). | W2: .
A3: Fire_LifeSafety | B3: Fire Fighting | C3: Detector | D3: FL-DT-002 | E3: Smoke/heat detector functional test | F3: Response within manufacturer spec | G3: Visual Inspection | H3: FLS-03-D-002 | I3: Level 02 - Office Area | J3: PHOTO-FIR-0002 | K3: Photo | L3: 3 | M3: =Table9[[#This Row],[Rate (Please Select from the list)]]/5 -> 0.6 | N3: 3.31 | O3: =Table9[[#This Row],[Score %]]*Table9[[#This Row],[Item Weight (Please Select from the list)]] -> 1.986 | P3: 5 | Q3: MEP Contractor | S3: P3 | U3: Closed | V3: Condition acceptable but requires attention; minor deficiencies observed. Trend indicates aging components; prioritize within next maintenance cycle. | W3: .
A4: Fire_LifeSafety | B4: Smoke Control | C4: Manual Call Point | D4: FL-MCP-003 | E4: Manual call point activation test | F4: Activates alarm; location correct | G4: Visual Inspection | H4: FLS-05-C-003 | I4: External - Service Yard | J4: PHOTO-FIR-0003 | K4: Photo | L4: 3 | M4: =Table9[[#This Row],[Rate (Please Select from the list)]]/5 -> 0.6 | N4: 2.65 | O4: =Table9[[#This Row],[Score %]]*Table9[[#This Row],[Item Weight (Please Select from the list)]] -> 1.59 | P4: 4 | Q4: Specialist Vendor | R4: CAPA-0001 | S4: P2 | T4: 45421 | U4: In Progress | V4: Condition acceptable but requires attention; minor deficiencies observed. Preventive maintenance records incomplete; verify PM completion. | W4: .
A5: Fire_LifeSafety | B5: Compartmentation | C5: Sounder and Beacon | D5: FL-SB-004 | E5: Audible/visual alarm device test | F5: Sound level ≥75dB(A); lights visible | G5: Visual Inspection | H5: FLS-03-C-004 | I5: External - Service Yard | J5: PHOTO-FIR-0004 | K5: Photo | L5: 3 | M5: =Table9[[#This Row],[Rate (Please Select from the list)]]/5 -> 0.6 | N5: 3.31 | O5: =Table9[[#This Row],[Score %]]*Table9[[#This Row],[Item Weight (Please Select from the list)]] -> 1.986 | P5: 5 | Q5: Specialist Vendor | R5: CAPA-0002 | S5: P2 | T5: 45421 | U5: Open | V5: Condition acceptable but requires attention; minor deficiencies observed. Evidence captured; recommend rectification and re-test. | W5: .
A6: Fire_LifeSafety | B6: Emergency Lighting | C6: Voice Evacuation System | D6: FL-VE-005 | E6: Voice evacuation system test | F6: Clear audio; zoning correct | G6: Visual Inspection | H6: FLS-04-C-005 | I6: Level 01 - Office Area | J6: PHOTO-FIR-0005 | K6: Photo | L6: 3 | M6: =Table9[[#This Row],[Rate (Please Select from the list)]]/5 -> 0.6 | N6: 2.65 | O6: =Table9[[#This Row],[Score %]]*Table9[[#This Row],[Item Weight (Please Select from the list)]] -> 1.59 | P6: 4 | Q6: Specialist Vendor | R6: CAPA-0003 | S6: P2 | T6: 45421 | U6: In Progress | V6: Condition acceptable but requires attention; minor deficiencies observed. Evidence captured; recommend rectification and re-test. | W6: .
A7: Fire_LifeSafety | B7: Fire Alarm | C7: Fire Alarm Control Panel | D7: FL-BT-006 | E7: Battery backup duration test | F7: ≥30 minutes autonomy | G7: Visual Inspection | H7: FLS-02-C-006 | I7: Staircase Core | J7: PHOTO-FIR-0006 | K7: Photo | L7: 1 | M7: =Table9[[#This Row],[Rate (Please Select from the list)]]/5 -> 0.2 | N7: 2.65 | O7: =Table9[[#This Row],[Score %]]*Table9[[#This Row],[Item Weight (Please Select from the list)]] -> 0.53 | P7: 4 | Q7: Specialist Vendor | R7: CAPA-0004 | S7: P1 | T7: 22/08/2024 | U7: Open | V7: Critical deficiency observed; immediate corrective action required to mitigate risk. Trend indicates aging components; prioritize within next maintenance cycle. | W7: .
A8: Fire_LifeSafety | B8: Interfaces | C8: Fire Pump | D8: FL-FP-007 | E8: Fire pump auto-start test | F8: Starts within 30s of pressure drop | G8: Visual Inspection | H8: FLS-01-B-007 | I8: Electrical Room - LV | J8: PHOTO-FIR-0007 | K8: Photo | L8: 3 | M8: =Table9[[#This Row],[Rate (Please Select from the list)]]/5 -> 0.6 | N8: 3.31 | O8: =Table9[[#This Row],[Score %]]*Table9[[#This Row],[Item Weight (Please Select from the list)]] -> 1.986 | P8: 5 | Q8: FM Contractor | S8: P3 | U8: Verified | V8: Condition acceptable but requires attention; minor deficiencies observed. Preventive maintenance records incomplete; verify PM completion. | W8: .
A9: Fire_LifeSafety | B9: Documentation | C9: Jockey Pump | D9: FL-JP-008 | E9: Jockey pump operation test | F9: Maintains pressure; cycles correctly | G9: Visual Inspection | H9: FLS-04-D-008 | I9: External - Service Yard | J9: PHOTO-FIR-0008 | K9: Photo | L9: 2 | M9: =Table9[[#This Row],[Rate (Please Select from the list)]]/5 -> 0.4 | N9: 3.31 | O9: =Table9[[#This Row],[Score %]]*Table9[[#This Row],[Item Weight (Please Select from the list)]] -> 1.324 | P9: 5 | Q9: MEP Contractor | R9: CAPA-0005 | S9: P1 | T9: 22/08/2024 | U9: Open | V9: Non-compliance / degraded condition observed; corrective action required. Observed corrosion/dust accumulation due to harsh environment; clean and protect. | W9: .
A10: Fire_LifeSafety | B10: Training | C10: Sprinkler System | D10: FL-SS-009 | E10: Sprinkler system pressure test | F10: Pressure stable; no leaks | G10: Visual Inspection | H10: FLS-03-A-009 | I10: Parking - Basement | J10: PHOTO-FIR-0009 | K10: Photo | L10: 3 | M10: =Table9[[#This Row],[Rate (Please Select from the list)]]/5 -> 0.6 | N10: 3.31 | O10: =Table9[[#This Row],[Score %]]*Table9[[#This Row],[Item Weight (Please Select from the list)]] -> 1.986 | P10: 5 | Q10: FM Contractor | R10: CAPA-0006 | S10: P2 | T10: 45421 | U10: In Progress | V10: Condition acceptable but requires attention; minor deficiencies observed. Observed corrosion/dust accumulation due to harsh environment; clean and protect. | W10: .
A11: Fire_LifeSafety | B11: Records | C11: Hydrant / Hose Reel | D11: FL-HH-010 | E11: Hydrant/hose reel flow test | F11: Adequate flow/pressure; valves operable | G11: Visual Inspection | H11: FLS-05-C-010 | I11: Roof - Mechanical Area | J11: PHOTO-FIR-0010 | K11: Photo | L11: 1 | M11: =Table9[[#This Row],[Rate (Please Select from the list)]]/5 -> 0.2 | N11: 2.65 | O11: =Table9[[#This Row],[Score %]]*Table9[[#This Row],[Item Weight (Please Select from the list)]] -> 0.53 | P11: 4 | Q11: Specialist Vendor | R11: CAPA-0007 | S11: P1 | T11: 22/08/2024 | U11: Open | V11: Critical deficiency observed; immediate corrective action required to mitigate risk. Preventive maintenance records incomplete; verify PM completion. | W11: .
A12: Fire_LifeSafety | C12: Fire Extinguisher | D12: FL-FE-011 | E12: Fire extinguisher inspection | F12: In date; pressure ok; accessible | G12: Visual Inspection | H12: FLS-B1-C-011 | I12: Staircase Core | J12: PHOTO-FIR-0011 | K12: Photo | L12: 0 | M12: =Table9[[#This Row],[Rate (Please Select from the list)]]/5 -> 0 | N12: 2.65 | O12: =Table9[[#This Row],[Score %]]*Table9[[#This Row],[Item Weight (Please Select from the list)]] -> 0 | P12: 4 | Q12: FM Contractor | S12: - | U12: N/A | V12: Not applicable for this building / scope. | W12: .
A13: Fire_LifeSafety | C13: Clean Agent System | D13: FL-CA-012 | E13: Clean agent system readiness | F13: Pressure ok; nozzles unobstructed | G13: Visual Inspection | H13: FLS-01-C-012 | I13: Level 02 - Office Area | K13: Photo | L13: 4 | M13: =Table9[[#This Row],[Rate (Please Select from the list)]]/5 -> 0.8 | N13: 2.65 | O13: =Table9[[#This Row],[Score %]]*Table9[[#This Row],[Item Weight (Please Select from the list)]] -> 2.12 | P13: 4 | Q13: MEP Contractor | S13: P4 | U13: Verified | V13: Inspected and found generally compliant; minor observations noted (no immediate impact). | W13: .
A14: Fire_LifeSafety | B14: Fire Fighting | C14: Detector | D14: FL-SE-013 | E14: Smoke extract fan test | F14: Starts on command; airflow adequate | G14: Visual Inspection | H14: FLS-05-B-013 | I14: Level 01 - Office Area | K14: Test Report | L14: 4 | M14: =Table9[[#This Row],[Rate (Please Select from the list)]]/5 -> 0.8 | N14: 3.31 | O14: =Table9[[#This Row],[Score %]]*Table9[[#This Row],[Item Weight (Please Select from the list)]] -> 2.648 | P14: 5 | Q14: FM Contractor | S14: P4 | U14: Closed | V14: Inspected and found generally compliant; minor observations noted (no immediate impact). | W14: .
A15: Fire_LifeSafety | C15: Pressurization Fan | D15: FL-PF-014 | E15: Pressurization fan test | F15: Creates positive pressure as designed | G15: Visual Inspection | H15: FLS-G-C-014 | I15: Parking - Basement | J15: PHOTO-FIR-0014 | K15: Photo | L15: 2 | M15: =Table9[[#This Row],[Rate (Please Select from the list)]]/5 -> 0.4 | N15: 2.65 | O15: =Table9[[#This Row],[Score %]]*Table9[[#This Row],[Item Weight (Please Select from the list)]] -> 1.06 | P15: 4 | Q15: FM Contractor | R15: CAPA-0008 | S15: P1 | T15: 22/08/2024 | U15: In Progress | V15: Non-compliance / degraded condition observed; corrective action required. Evidence captured; recommend rectification and re-test. | W15: .
A16: Fire_LifeSafety | B16: Fire Fighting | C16: Detector | D16: FL-FD-015 | E16: Fire/smoke damper operation test | F16: Closes on signal; seals intact | G16: Visual Inspection | H16: FLS-03-B-015 | I16: Basement B1 - Plantroom | J16: PHOTO-FIR-0015 | K16: Photo | L16: 3 | M16: =Table9[[#This Row],[Rate (Please Select from the list)]]/5 -> 0.6 | N16: 3.31 | O16: =Table9[[#This Row],[Score %]]*Table9[[#This Row],[Item Weight (Please Select from the list)]] -> 1.986 | P16: 5 | Q16: MEP Contractor | S16: P3 | U16: Closed | V16: Condition acceptable but requires attention; minor deficiencies observed. Evidence captured; recommend rectification and re-test. | W16: .
A17: Fire_LifeSafety | C17: Fire Door | D17: FL-FD-016 | E17: Fire door inspection | F17: Self-closing; gaps ≤4mm; seals intact | G17: Visual Inspection | H17: FLS-G-B-016 | I17: External - Service Yard | K17: Test Report | L17: 4 | M17: =Table9[[#This Row],[Rate (Please Select from the list)]]/5 -> 0.8 | N17: 2.65 | O17: =Table9[[#This Row],[Score %]]*Table9[[#This Row],[Item Weight (Please Select from the list)]] -> 2.12 | P17: 4 | Q17: Specialist Vendor | S17: P4 | U17: Verified | V17: Inspected and found generally compliant; minor observations noted (no immediate impact). | W17: .
A18: Fire_LifeSafety | C18: Fire Curtain | D18: FL-FC-017 | E18: Fire curtain drop test | F18: Drops automatically; no obstruction | G18: Visual Inspection | H18: FLS-02-D-017 | I18: Electrical Room - LV | J18: PHOTO-FIR-0017 | K18: Photo | L18: 2 | M18: =Table9[[#This Row],[Rate (Please Select from the list)]]/5 -> 0.4 | N18: 2.65 | O18: =Table9[[#This Row],[Score %]]*Table9[[#This Row],[Item Weight (Please Select from the list)]] -> 1.06 | P18: 4 | Q18: MEP Contractor | R18: CAPA-0009 | S18: P1 | T18: 22/08/2024 | U18: Open | V18: Non-compliance / degraded condition observed; corrective action required. Evidence captured; recommend rectification and re-test. | W18: .
A19: Fire_LifeSafety | C19: Firestopping System | D19: FL-FS-018 | E19: Firestopping integrity check | F19: Penetrations sealed; material intact | G19: Visual Inspection | H19: FLS-02-B-018 | I19: Level 03 - Office Area | J19: PHOTO-FIR-0018 | K19: Photo | L19: 2 | M19: =Table9[[#This Row],[Rate (Please Select from the list)]]/5 -> 0.4 | N19: 2.65 | O19: =Table9[[#This Row],[Score %]]*Table9[[#This Row],[Item Weight (Please Select from the list)]] -> 1.06 | P19: 4 | Q19: MEP Contractor | R19: CAPA-0010 | S19: P1 | T19: 22/08/2024 | U19: Open | V19: Non-compliance / degraded condition observed; corrective action required. Preventive maintenance records incomplete; verify PM completion. | W19: .
A20: Fire_LifeSafety | C20: Emergency Light | D20: FL-EL-019 | E20: Emergency lighting duration test | F20: ≥90 minutes operation | G20: Visual Inspection | H20: FLS-B1-B-019 | I20: Level 01 - Office Area | K20: Checklist | L20: 4 | M20: =Table9[[#This Row],[Rate (Please Select from the list)]]/5 -> 0.8 | N20: 2.65 | O20: =Table9[[#This Row],[Score %]]*Table9[[#This Row],[Item Weight (Please Select from the list)]] -> 2.12 | P20: 4 | Q20: FM Contractor | S20: P4 | U20: Verified | V20: Inspected and found generally compliant; minor observations noted (no immediate impact). | W20: .
A21: Fire_LifeSafety | C21: Exit Sign | D21: FL-ES-020 | E21: Exit sign illumination test | F21: Clearly visible; illuminated | G21: Visual Inspection | H21: FLS-01-D-020 | I21: Staircase Core | J21: PHOTO-FIR-0020 | K21: Photo | L21: 3 | M21: =Table9[[#This Row],[Rate (Please Select from the list)]]/5 -> 0.6 | N21: 2.65 | O21: =Table9[[#This Row],[Score %]]*Table9[[#This Row],[Item Weight (Please Select from the list)]] -> 1.59 | P21: 4 | Q21: FM Contractor | S21: P2 | U21: Closed | V21: Condition acceptable but requires attention; minor deficiencies observed. Trend indicates aging components; prioritize within next maintenance cycle. | W21: .
A22: Fire_LifeSafety | C22: Central Battery System | D22: FL-CB-021 | E22: Central battery system test | F22: Charging ok; load test passed | G22: Visual Inspection | H22: FLS-B1-C-021 | I22: Basement B1 - Plantroom | J22: PHOTO-FIR-0021 | K22: Photo | L22: 3 | M22: =Table9[[#This Row],[Rate (Please Select from the list)]]/5 -> 0.6 | N22: 2.65 | O22: =Table9[[#This Row],[Score %]]*Table9[[#This Row],[Item Weight (Please Select from the list)]] -> 1.59 | P22: 4 | Q22: MEP Contractor | R22: CAPA-0011 | S22: P2 | T22: 45421 | U22: Open | V22: Condition acceptable but requires attention; minor deficiencies observed. Evidence captured; recommend rectification and re-test. | W22: .
A23: Fire_LifeSafety | C23: Elevator Recall Interface | D23: FL-ER-022 | E23: Elevator recall interface test | F23: Elevators recall to designated floor | G23: Visual Inspection | H23: FLS-03-B-022 | I23: External - Service Yard | J23: PHOTO-FIR-0022 | K23: Photo | L23: 3 | M23: =Table9[[#This Row],[Rate (Please Select from the list)]]/5 -> 0.6 | N23: 2.65 | O23: =Table9[[#This Row],[Score %]]*Table9[[#This Row],[Item Weight (Please Select from the list)]] -> 1.59 | P23: 4 | Q23: Specialist Vendor | S23: P3 | U23: Closed | V23: Condition acceptable but requires attention; minor deficiencies observed. Preventive maintenance records incomplete; verify PM completion. | W23: .
A24: Fire_LifeSafety | C24: Access Control Fire Release | D24: FL-AC-023 | E24: Access control release test | F24: Doors unlock on fire signal | G24: Visual Inspection | H24: FLS-01-B-023 | I24: Level 03 - Office Area | J24: PHOTO-FIR-0023 | K24: Photo | L24: 3 | M24: =Table9[[#This Row],[Rate (Please Select from the list)]]/5 -> 0.6 | N24: 2.65 | O24: =Table9[[#This Row],[Score %]]*Table9[[#This Row],[Item Weight (Please Select from the list)]] -> 1.59 | P24: 4 | Q24: Specialist Vendor | R24: CAPA-0012 | S24: P2 | T24: 45421 | U24: In Progress | V24: Condition acceptable but requires attention; minor deficiencies observed. Preventive maintenance records incomplete; verify PM completion. | W24: .
A25: Fire_LifeSafety | C25: BMS Interface | D25: FL-BI-024 | E25: BMS interface verification | F25: Alarms received; HVAC shutdown works | G25: Visual Inspection | H25: FLS-B1-B-024 | I25: Staircase Core | J25: PHOTO-FIR-0024 | K25: Photo | L25: 3 | M25: =Table9[[#This Row],[Rate (Please Select from the list)]]/5 -> 0.6 | N25: 2.65 | O25: =Table9[[#This Row],[Score %]]*Table9[[#This Row],[Item Weight (Please Select from the list)]] -> 1.59 | P25: 4 | Q25: MEP Contractor | R25: CAPA-0013 | S25: P2 | T25: 45421 | U25: In Progress | V25: Condition acceptable but requires attention; minor deficiencies observed. Evidence captured; recommend rectification and re-test. | W25: .
A26: Fire_LifeSafety | C26: HVAC Shutdown Interface | D26: FL-HS-025 | E26: HVAC shutdown test | F26: AHUs/Fans stop on fire signal | G26: Visual Inspection | H26: FLS-04-C-025 | I26: External - Service Yard | J26: PHOTO-FIR-0025 | K26: Photo | L26: 2 | M26: =Table9[[#This Row],[Rate (Please Select from the list)]]/5 -> 0.4 | N26: 2.65 | O26: =Table9[[#This Row],[Score %]]*Table9[[#This Row],[Item Weight (Please Select from the list)]] -> 1.06 | P26: 4 | Q26: MEP Contractor | R26: CAPA-0014 | S26: P1 | T26: 22/08/2024 | U26: In Progress | V26: Non-compliance / degraded condition observed; corrective action required. Evidence captured; recommend rectification and re-test. | W26: .
A27: Fire_LifeSafety | C27: Civil Defense Certification | D27: FL-CD-026 | E27: Civil defense certification | F27: Valid certificate available | G27: Visual Inspection | H27: FLS-03-B-026 | I27: Roof - Mechanical Area | J27: PHOTO-FIR-0026 | K27: Photo | L27: 3 | M27: =Table9[[#This Row],[Rate (Please Select from the list)]]/5 -> 0.6 | N27: 2.65 | O27: =Table9[[#This Row],[Score %]]*Table9[[#This Row],[Item Weight (Please Select from the list)]] -> 1.59 | P27: 4 | Q27: Specialist Vendor | S27: P3 | U27: Closed | V27: Condition acceptable but requires attention; minor deficiencies observed. Housekeeping and labeling improvements required. | W27: .
A28: Fire_LifeSafety | C28: Fire Strategy Drawings | D28: FL-FS-027 | E28: Fire strategy drawing verification | F28: Matches as-built; accessible | G28: Visual Inspection | H28: FLS-04-D-027 | I28: Level 03 - Office Area | J28: PHOTO-FIR-0027 | K28: Photo | L28: 3 | M28: =Table9[[#This Row],[Rate (Please Select from the list)]]/5 -> 0.6 | N28: 2.65 | O28: =Table9[[#This Row],[Score %]]*Table9[[#This Row],[Item Weight (Please Select from the list)]] -> 1.59 | P28: 4 | Q28: FM Contractor | R28: CAPA-0015 | S28: P2 | T28: 45421 | U28: Open | V28: Condition acceptable but requires attention; minor deficiencies observed. Housekeeping and labeling improvements required. | W28: .
A29: Fire_LifeSafety | C29: Fire System Test Certificates | D29: FL-TC-028 | E29: Fire system test certificates | F29: Complete set available | G29: Visual Inspection | H29: FLS-G-A-028 | I29: Roof - Mechanical Area | J29: PHOTO-FIR-0028 | K29: Photo | L29: 1 | M29: =Table9[[#This Row],[Rate (Please Select from the list)]]/5 -> 0.2 | N29: 3.31 | O29: =Table9[[#This Row],[Score %]]*Table9[[#This Row],[Item Weight (Please Select from the list)]] -> 0.662 | P29: 5 | Q29: FM Contractor | R29: CAPA-0016 | S29: P1 | T29: 22/08/2024 | U29: Open | V29: Critical deficiency observed; immediate corrective action required to mitigate risk. Housekeeping and labeling improvements required. | W29: .
A30: Fire_LifeSafety | B30: Fire Alarm | C30: Fire Alarm Control Panel | D30: FL-OP-029 | E30: Fire panel operator training | F30: FM staff trained; records available | G30: Visual Inspection | H30: FLS-04-A-029 | I30: Roof - Mechanical Area | J30: PHOTO-FIR-0029 | K30: Photo | L30: 3 | M30: =Table9[[#This Row],[Rate (Please Select from the list)]]/5 -> 0.6 | N30: 2.65 | O30: =Table9[[#This Row],[Score %]]*Table9[[#This Row],[Item Weight (Please Select from the list)]] -> 1.59 | P30: 4 | Q30: Specialist Vendor | R30: CAPA-0017 | S30: P3 | T30: 29/09/2024 | U30: In Progress | V30: Condition acceptable but requires attention; minor deficiencies observed. Preventive maintenance records incomplete; verify PM completion. | W30: .
A31: Fire_LifeSafety | B31: Interfaces | C31: Fire Pump | D31: FL-MP-030 | E31: Fire pump monthly run test | F31: Records available; pump operational | G31: Visual Inspection | H31: FLS-02-A-030 | I31: Level 01 - Office Area | J31: PHOTO-FIR-0030 | K31: Photo | L31: 3 | M31: =Table9[[#This Row],[Rate (Please Select from the list)]]/5 -> 0.6 | N31: 3.31 | O31: =Table9[[#This Row],[Score %]]*Table9[[#This Row],[Item Weight (Please Select from the list)]] -> 1.986 | P31: 5 | Q31: FM Contractor | S31: P2 | U31: Closed | V31: Condition acceptable but requires attention; minor deficiencies observed. Preventive maintenance records incomplete; verify PM completion. | W31: .
A32: Fire_LifeSafety | C32: Fire Door | D32: FL-FI-031 | E32: Fire door inspection log | F32: Regular inspections documented | G32: Visual Inspection | H32: FLS-02-A-031 | I32: Electrical Room - LV | J32: PHOTO-FIR-0031 | K32: Photo | L32: 1 | M32: =Table9[[#This Row],[Rate (Please Select from the list)]]/5 -> 0.2 | N32: 2.65 | O32: =Table9[[#This Row],[Score %]]*Table9[[#This Row],[Item Weight (Please Select from the list)]] -> 0.53 | P32: 4 | Q32: FM Contractor | R32: CAPA-0018 | S32: P1 | T32: 22/08/2024 | U32: In Progress | V32: Critical deficiency observed; immediate corrective action required to mitigate risk. Housekeeping and labeling improvements required. | W32: .
A33: Fire_LifeSafety | B33: Fire Fighting | C33: Detector | D33: FL-SC-032 | E33: Smoke control sequence verification | F33: Sequences match fire strategy | G33: Visual Inspection | H33: FLS-05-A-032 | I33: Level 03 - Office Area | J33: PHOTO-FIR-0032 | K33: Photo | L33: 3 | M33: =Table9[[#This Row],[Rate (Please Select from the list)]]/5 -> 0.6 | N33: 3.31 | O33: =Table9[[#This Row],[Score %]]*Table9[[#This Row],[Item Weight (Please Select from the list)]] -> 1.986 | P33: 5 | Q33: Specialist Vendor | S33: P3 | U33: Verified | V33: Condition acceptable but requires attention; minor deficiencies observed. Observed corrosion/dust accumulation due to harsh environment; clean and protect. | W33: .
A34: Fire_LifeSafety | B34: Fire Alarm | C34: Fire Alarm Control Panel | D34: FL-ZN-033 | E34: Zone identification accuracy | F34: Panel display matches physical zones | G34: Visual Inspection | H34: FLS-03-C-033 | I34: Basement B1 - Plantroom | J34: PHOTO-FIR-0033 | K34: Photo | L34: 2 | M34: =Table9[[#This Row],[Rate (Please Select from the list)]]/5 -> 0.4 | N34: 2.65 | O34: =Table9[[#This Row],[Score %]]*Table9[[#This Row],[Item Weight (Please Select from the list)]] -> 1.06 | P34: 4 | Q34: FM Contractor | R34: CAPA-0019 | S34: P2 | T34: 45421 | U34: In Progress | V34: Non-compliance / degraded condition observed; corrective action required. Housekeeping and labeling improvements required. | W34: .
A35: Fire_LifeSafety | B35: Fire Alarm | C35: Fire Alarm Control Panel | D35: FL-RS-034 | E35: Emergency responder communication test | F35: Tested with authorities if required | G35: Visual Inspection | H35: FLS-03-B-034 | I35: Roof - Mechanical Area | J35: PHOTO-FIR-0034 | K35: Photo | L35: 3 | M35: =Table9[[#This Row],[Rate (Please Select from the list)]]/5 -> 0.6 | N35: 2.65 | O35: =Table9[[#This Row],[Score %]]*Table9[[#This Row],[Item Weight (Please Select from the list)]] -> 1.59 | P35: 4 | Q35: MEP Contractor | R35: CAPA-0020 | S35: P2 | T35: 45421 | U35: In Progress | V35: Condition acceptable but requires attention; minor deficiencies observed. Observed corrosion/dust accumulation due to harsh environment; clean and protect. | W35: .
A36: Fire_LifeSafety | C36: Fire Drill Records | D36: FL-DR-035 | E36: Fire drill records | F36: Regular drills conducted; documented | G36: Visual Inspection | H36: FLS-04-D-035 | I36: Roof - Mechanical Area | J36: PHOTO-FIR-0035 | K36: Photo | L36: 3 | M36: =Table9[[#This Row],[Rate (Please Select from the list)]]/5 -> 0.6 | N36: 2.65 | O36: =Table9[[#This Row],[Score %]]*Table9[[#This Row],[Item Weight (Please Select from the list)]] -> 1.59 | P36: 4 | Q36: Specialist Vendor | S36: P3 | U36: Verified | V36: Condition acceptable but requires attention; minor deficiencies observed. Observed corrosion/dust accumulation due to harsh environment; clean and protect. | W36: .
A37: Electrical | B37: Power Distribution | C37: Main LV Switchboard | D37: EL-IR-001 | E37: Main feeder insulation resistance (Megger) | F37: MΩ values meet acceptance criteria | G37: Visual Inspection | H37: EL-02-A-036 | I37: Level 03 - Office Area | J37: PHOTO-ELE-0036 | K37: Photo | L37: 2 | M37: =Table9[[#This Row],[Rate (Please Select from the list)]]/5 -> 0.4 | N37: 3.31 | O37: =Table9[[#This Row],[Score %]]*Table9[[#This Row],[Item Weight (Please Select from the list)]] -> 1.324 | P37: 4 | Q37: MEP Contractor | R37: CAPA-0021 | S37: P1 | T37: 22/08/2024 | U37: In Progress | V37: Non-compliance / degraded condition observed; corrective action required. Preventive maintenance records incomplete; verify PM completion. | W37: .
A38: Electrical | B38: Power Distribution | C38: Main LV Switchboard | D38: EL-CT-002 | E38: Circuit continuity test (random sample) | F38: Ω within acceptable range, no open circuits | G38: Visual Inspection | H38: EL-04-A-037 | I38: Level 03 - Office Area | K38: Test Report | L38: 4 | M38: =Table9[[#This Row],[Rate (Please Select from the list)]]/5 -> 0.8 | N38: 3.31 | O38: =Table9[[#This Row],[Score %]]*Table9[[#This Row],[Item Weight (Please Select from the list)]] -> 2.648 | P38: 4 | Q38: MEP Contractor | S38: P3 | U38: Verified | V38: Inspected and found generally compliant; minor observations noted (no immediate impact). | W38: .
A39: Electrical | B39: Power Distribution | C39: Main LV Switchboard | D39: EL-LD-003 | E39: Load test / load profiling (peak hour) | F39: Load % within design, no overload | G39: Visual Inspection | H39: EL-G-A-038 | I39: Basement B1 - Plantroom | K39: Photo | L39: 4 | M39: =Table9[[#This Row],[Rate (Please Select from the list)]]/5 -> 0.8 | N39: 3.31 | O39: =Table9[[#This Row],[Score %]]*Table9[[#This Row],[Item Weight (Please Select from the list)]] -> 2.648 | P39: 4 | Q39: FM Contractor | S39: P3 | U39: Closed | V39: Inspected and found generally compliant; minor observations noted (no immediate impact). | W39: .
A40: Electrical | B40: Lighting | C40: Earthing System | D40: EL-ER-004 | E40: Earth resistance test | F40: Ω meets acceptance limit | G40: Visual Inspection | H40: EL-02-D-039 | I40: Level 02 - Office Area | K40: Photo | L40: 4 | M40: =Table9[[#This Row],[Rate (Please Select from the list)]]/5 -> 0.8 | N40: 3.31 | O40: =Table9[[#This Row],[Score %]]*Table9[[#This Row],[Item Weight (Please Select from the list)]] -> 2.648 | P40: 4 | Q40: Specialist Vendor | R40: CAPA-0022 | S40: P3 | T40: 29/09/2024 | U40: In Progress | V40: Inspected and found generally compliant; minor observations noted (no immediate impact). | W40: .
...

Sheet Test Register
A1: Test ID | B1: Test Name | C1: System | D1: Standard / Reference | E1: Instrument | F1: Locations / Sampling | G1: Acceptance Criteria | H1: Readings | I1: Pass/Fail | J1: Linked Item Codes | K1: Evidence Ref | L1: Witness | M1: Date
A2: TR-001 | B2: Fire Alarm Cause & Effect Test | C2: Fire_LifeSafety | D2: NFPA 20/25 | E2: Laptop + programming tool / panel access | F2: Ground + typical floor | G2: All devices report correctly; outputs match matrix; no faults | H2: All zones OK; 1 device delay 2s | I2: Pass | J2: FL-CD-026, FL-SB-004 | K2: TR-001-FIR | L2: Client Rep | M2: 45999
A3: TR-002 | B3: Smoke/Heat Detector Functional Test (sample) | C3: Fire_LifeSafety | D3: SBC 801 (Fire Code) | E3: Test smoke / heat gun | F3: Random sample (10%) | G3: Alarm within manufacturer spec; address correct | H3: Response 3–8s; addresses OK | I3: Pass | J3: FL-SB-004, FL-ZN-033, FL-PF-014 | K3: TR-002-FIR | L3: Client Rep | M3: 46000
A4: TR-003 | B4: Manual Call Point Activation Test (sample) | C4: Fire_LifeSafety | D4: SBC 801 (Fire Code) | E4: Key + panel access | F4: Stair cores / exits (sample) | G4: Alarm activates; correct location displayed | H4: Activated OK; reset OK | I4: Pass | J4: FL-FS-027, FL-VE-005, FL-FD-016 | K4: TR-003-FIR | L4: Client Rep | M4: 46001
A5: TR-004 | B5: Fire Pump Start & Pressure Test | C5: Fire_LifeSafety | D5: Civil Defense Requirements | E5: Pressure gauge + flow meter | F5: Basement pump room | G5: Auto start; pressure within design; no abnormal vibration | H5: Pressure 7.0 bar (design 7.5) | I5: Need Attention | J5: FL-JP-008, FL-FD-015 | K5: TR-004-FIR | L5: Specialist Vendor | M5: 46002
A6: TR-005 | B6: Jockey Pump Auto Cut-in/out Test | C6: Fire_LifeSafety | D6: SBC 801 (Fire Code) | E6: Pressure gauge | F6: Basement pump room | G6: Cuts-in/out within setpoints | H6: Cut-in 6.6 bar; cut-out 7.2 bar | I6: Pass | J6: FL-CD-026, FL-SB-004, FL-FD-015, FL-MCP-003 | K6: TR-005-FIR | L6: Specialist Vendor | M6: 46003
A7: TR-006 | B7: Sprinkler System Visual + Valve Position Check | C7: Fire_LifeSafety | D7: NFPA 72 | E7: Checklist | F7: Risers / control valves | G7: Valves sealed open; gauges normal; no leaks | H7: All OK; minor label missing | I7: Pass | J7: FL-FS-027, FL-HH-010, FL-DR-035 | K7: TR-006-FIR | L7: Client Rep | M7: 46004
A8: TR-007 | B8: Hydrant/Hose Reel Flow Test (sample) | C8: Fire_LifeSafety | D8: NFPA 20/25 | E8: Flow/pressure gauge | F8: Typical floor + basement | G8: Flow and pressure meet requirement; hose condition OK | H8: Basement reel kink noted | I8: Need Attention | J8: FL-CA-012, FL-FP-007, FL-SE-013, FL-BI-024 | K8: TR-007-FIR | L8: Client Rep | M8: 46005
A9: TR-008 | B9: Emergency Lighting Duration Test (sample) | C9: Fire_LifeSafety | D9: SBC 801 (Fire Code) | E9: Lux meter + timer | F9: Egress routes (sample) | G9: ≥ 90 min autonomy; adequate illumination | H9: Autonomy 95 min; lux OK | I9: Pass | J9: FL-SB-004, FL-PF-014, FL-SC-032, FL-DR-035 | K9: TR-008-FIR | L9: MEP Supervisor | M9: 46006
A10: TR-009 | B10: Exit Sign Visibility Check | C10: Fire_LifeSafety | D10: NFPA 20/25 | E10: Visual inspection | F10: All exits | G10: Signs illuminated and visible | H10: 2 signs dim in corridor | I10: Need Attention | J10: FL-MP-030, FL-BI-024, FL-ES-020 | K10: TR-009-FIR | L10: FM Manager | M10: 46007
A11: TR-010 | B11: Civil Defense Certificates Review | C11: Fire_LifeSafety | D11: NFPA 72 | E11: Document review | F11: Document set | G11: Valid certificates provided | H11: Some certificates not available on site | I11: Need Attention | J11: FL-FD-016, FL-BT-006, FL-ES-020, FL-RS-034 | K11: TR-010-FIR | L11: MEP Supervisor | M11: 46008
A12: TR-011 | B12: Main Feeder Insulation Resistance (Megger) | C12: Electrical | D12: IEEE Std 43 (IR) | E12: Insulation resistance tester (5kV) | F12: Main feeders (sample) | G12: IR meets acceptance; stable readings | H12: ≥500 MΩ measured | I12: Pass | J12: EL-FST-019, EL-ELX-010, EL-BMS-025, EL-LD-003 | K12: TR-011-ELE | L12: Client Rep | M12: 46009
A13: TR-012 | B13: Earth Resistance Test | C13: Electrical | D13: SBC 401 (Electrical) | E13: Earth tester | F13: Earthing pit(s) / main bar | G13: ≤ 1–2 Ω (project spec) | H13: 0.9 Ω measured | I13: Pass | J13: EL-COM-030, EL-MTR-015 | K13: TR-012-ELE | L13: FM Manager | M13: 46010
... A81: TR-080 | B81: Leak Inspection - Wet Areas | C81: Plumbing_Water | D81: SBC Plumbing Code | E81: Visual inspection | F81: Basement + roof plantrooms | G81: No leaks; traps intact | H81: Minor seepage under one basin | I81: Pass | J81: PL-LK-004, PL-FLW-002, PL-RES-035, PL-DRN-016 | K81: TR-080-PLU | L81: MEP Supervisor | M81: 46078

Sheet CAPA Register
A1: Corrective and Preventive Action (CAPA) ID | B1: Priority | C1: System | D1: Item Code | E1: Finding | F1: Required Action | G1: Responsibility | H1: Due Date | I1: Estimated Cost | J1: Status | K1: Verification Evidence
A2: CAPA-0001 | B2: P2 | C2: Fire_LifeSafety | D2: FL-MCP-003 | E2: Condition acceptable but requires attention; minor deficiencies observed. Preventive maintenance records incomplete; verify PM completion. | F2: Submit missing certificates and update compliance records. | G2: Specialist Vendor | H2: 05/09/2024 | I2: SAR 22,500 | J2: Open
A3: CAPA-0002 | B3: P2 | C3: Fire_LifeSafety | D3: FL-SB-004 | E3: Condition acceptable but requires attention; minor deficiencies observed. Evidence captured; recommend rectification and re-test. | F3: Submit missing certificates and update compliance records. | G3: Specialist Vendor | H3: 05/09/2024 | I3: SAR 24,000 | J3: Open
A4: CAPA-0003 | B4: P2 | C4: Fire_LifeSafety | D4: FL-VE-005 | E4: Condition acceptable but requires attention; minor deficiencies observed. Evidence captured; recommend rectification and re-test. | F4: Replace faulty device and update fire alarm panel programming. | G4: Specialist Vendor | H4: 05/09/2024 | I4: SAR 13,500 | J4: Open
A5: CAPA-0004 | B5: P1 | C5: Fire_LifeSafety | D5: FL-BT-006 | E5: Critical deficiency observed; immediate corrective action required to mitigate risk. Trend indicates aging components; prioritize within next maintenance cycle. | F5: Submit missing certificates and update compliance records. | G5: Specialist Vendor | H5: 22/08/2024 | I5: SAR 59,000 | J5: Open
A6: CAPA-0005 | B6: P1 | C6: Fire_LifeSafety | D6: FL-JP-008 | E6: Non-compliance / degraded condition observed; corrective action required. Observed corrosion/dust accumulation due to harsh environment; clean and protect. | F6: Replace faulty device and update fire alarm panel programming. | G6: MEP Contractor | H6: 22/08/2024 | I6: SAR 26,000 | J6: Open
A7: CAPA-0006 | B7: P2 | C7: Fire_LifeSafety | D7: FL-SS-009 | E7: Condition acceptable but requires attention; minor deficiencies observed. Observed corrosion/dust accumulation due to harsh environment; clean and protect. | F7: Submit missing certificates and update compliance records. | G7: FM Contractor | H7: 05/09/2024 | I7: SAR 17,500 | J7: Open
A8: CAPA-0007 | B8: P1 | C8: Fire_LifeSafety | D8: FL-HH-010 | E8: Critical deficiency observed; immediate corrective action required to mitigate risk. Preventive maintenance records incomplete; verify PM completion. | F8: Replace faulty device and update fire alarm panel programming. | G8: Specialist Vendor | H8: 22/08/2024 | I8: SAR 25,500 | J8: Open
A9: CAPA-0008 | B9: P1 | C9: Fire_LifeSafety | D9: FL-PF-014 | E9: Non-compliance / degraded condition observed; corrective action required. Evidence captured; recommend rectification and re-test. | F9: Rectify defect and re-test system in coordination with Civil Defense requirements. | G9: FM Contractor | H9: 22/08/2024 | I9: SAR 58,000 | J9: Open
A10: CAPA-0009 | B10: P1 | C10: Fire_LifeSafety | D10: FL-FC-017 | E10: Non-compliance / degraded condition observed; corrective action required. Evidence captured; recommend rectification and re-test. | F10: Submit missing certificates and update compliance records. | G10: MEP Contractor | H10: 22/08/2024 | I10: SAR 48,500 | J10: Open
A11: CAPA-0010 | B11: P1 | C11: Fire_LifeSafety | D11: FL-FS-018 | E11: Non-compliance / degraded condition observed; corrective action required. Preventive maintenance records incomplete; verify PM completion. | F11: Replace faulty device and update fire alarm panel programming. | G11: MEP Contractor | H11: 22/08/2024 | I11: SAR 59,500 | J11: Open
A12: CAPA-0011 | B12: P2 | C12: Fire_LifeSafety | D12: FL-CB-021 | E12: Condition acceptable but requires attention; minor deficiencies observed. Evidence captured; recommend rectification and re-test. | F12: Rectify defect and re-test system in coordination with Civil Defense requirements. | G12: MEP Contractor | H12: 05/09/2024 | I12: SAR 24,500 | J12: Open
A13: CAPA-0012 | B13: P2 | C13: Fire_LifeSafety | D13: FL-AC-023 | E13: Condition acceptable but requires attention; minor deficiencies observed. Preventive maintenance records incomplete; verify PM completion. | F13: Rectify defect and re-test system in coordination with Civil Defense requirements. | G13: Specialist Vendor | H13: 05/09/2024 | I13: SAR 9,500 | J13: Open
... A46: CAPA-0045 | B46: P1 | C46: Mechanical_HVAC | D46: ME-CLN-033 | E46: Non-compliance / degraded condition observed; corrective action required. Trend indicates aging components; prioritize within next maintenance cycle. | F46: Carry out corrective maintenance and re-test system performance. | G46: Main Contractor | H46: 22/08/2024 | I46: SAR 55,500 | J46: Open
